Workbook

Sheet Summary
A1: VitalScan: Smoking Health Risk Analysis
A2: Key numbers, Excel layer
A4: Total patients | C4: Average age
A5: =COUNTA('Raw Data'!A2:A2501) -> 2500 | C5: =ROUND(AVERAGE('Raw Data'!B2:B2501),1) -> 54
A7: Average BMI | C7: Current smokers (%)
A8: =ROUND(AVERAGE('Raw Data'!I2:I2501),1) -> 29.6 | C8: =ROUND(COUNTIF('Raw Data'!D2:D2501,"Current")/COUNTA('Raw Data'!A2:A2501)*100,1) -> 29.3
A10: Average cholesterol | C10: High risk patients
A11: =ROUND(AVERAGE('Raw Data'!K2:K2501),1) -> 207.8 | C11: =COUNTIF('Risk Score'!J2:J2501,"High") -> 246
A13: High risk (%) | C13: Damaged organ cases
A14: =ROUND(COUNTIF('Risk Score'!J2:J2501,"High")/COUNTA('Raw Data'!A2:A2501)*100,1) -> 9.8 | C14: =COUNTIF('Raw Data'!H2:H2501,"Damaged") -> 897
A17: High risk patients are ranked by score on the Priority Screening List sheet.

Sheet Raw Data
A1: Patient_ID | B1: Age | C1: Gender | D1: Smoking_Status | E1: Years_of_Smoking | F1: Cigarettes_Per_Day | G1: Organ | H1: Organ_Condition | I1: BMI | J1: BP_Risk | K1: Cholesterol_Level | L1: Family_History_Risk | M1: Alcohol_Consumption
A2: 17 | B2: 55 | C2: Female | D2: Never | E2: 0 | F2: 0 | G2: Liver | H2: Healthy | I2: 32.8 | J2: Normal | K2: 136.3 | L2: No | M2: Low
A3: 18 | B3: 20 | C3: Female | D3: Never | E3: 0 | F3: 0 | G3: Kidney | H3: Damaged | I3: 17.4 | J3: Normal | K3: 160.8 | L3: No | M3: Low
A4: 31 | B4: 64 | C4: Male | D4: Never | E4: 0 | F4: 0 | G4: Kidney | H4: Healthy | I4: 41.2 | J4: Normal | K4: 127.4 | L4: No | M4: Low
A5: 115 | B5: 65 | C5: Male | D5: Never | E5: 0 | F5: 0 | G5: Liver | H5: Damaged | I5: 34.4 | J5: Normal | K5: 231.4 | L5: No | M5: Low
A6: 135 | B6: 24 | C6: Female | D6: Never | E6: 0 | F6: 0 | G6: Human Body | H6: Damaged | I6: 35.2 | J6: Normal | K6: 196.6 | L6: No | M6: Low
A7: 140 | B7: 40 | C7: Male | D7: Never | E7: 0 | F7: 0 | G7: Heart | H7: Damaged | I7: 28.1 | J7: Normal | K7: 200.8 | L7: No | M7: Low
A8: 154 | B8: 69 | C8: Female | D8: Never | E8: 0 | F8: 0 | G8: Heart | H8: Damaged | I8: 30.3 | J8: Normal | K8: 136.1 | L8: No | M8: Low
A9: 159 | B9: 54 | C9: Male | D9: Never | E9: 0 | F9: 0 | G9: Heart | H9: Healthy | I9: 30.7 | J9: Normal | K9: 190.4 | L9: No | M9: Low
A10: 193 | B10: 21 | C10: Female | D10: Never | E10: 0 | F10: 0 | G10: Lungs | H10: Damaged | I10: 31.8 | J10: Normal | K10: 194.3 | L10: No | M10: Low
A11: 215 | B11: 42 | C11: Male | D11: Never | E11: 0 | F11: 0 | G11: Human Body | H11: Healthy | I11: 37.6 | J11: Normal | K11: 188.2 | L11: No | M11: Low
A12: 233 | B12: 26 | C12: Female | D12: Never | E12: 0 | F12: 0 | G12: Liver | H12: Healthy | I12: 37.5 | J12: Normal | K12: 278.4 | L12: No | M12: Low
A13: 240 | B13: 38 | C13: Female | D13: Never | E13: 0 | F13: 0 | G13: Heart | H13: Healthy | I13: 33.8 | J13: Normal | K13: 175.1 | L13: No | M13: Low
... A2501: 2499 | B2501: 43 | C2501: Female | D2501: Current | E2501: 15 | F2501: 6 | G2501: Human Body | H2501: Healthy | I2501: 41.2 | J2501: Normal | K2501: 129.3 | L2501: Yes | M2501: Low

Sheet Validation
A1: Data Validation
A3: Check | B3: Result | C3: Expected
A4: Total rows | B4: =COUNTA('Raw Data'!A2:A2501) -> 2500 | C4: 2500
A5: Duplicate Patient IDs | B5: =SUMPRODUCT((COUNTIF('Raw Data'!A2:A2501,'Raw Data'!A2:A2501)>1)*1) -> 0 | C5: 0
A7: Missing values by column
A8: Column | B8: Blank Count
A9: Patient_ID | B9: =COUNTBLANK('Raw Data'!A2:A2501) -> 0
A10: Age | B10: =COUNTBLANK('Raw Data'!B2:B2501) -> 0
A11: Gender | B11: =COUNTBLANK('Raw Data'!C2:C2501) -> 0
A12: Smoking_Status | B12: =COUNTBLANK('Raw Data'!D2:D2501) -> 0
A13: Years_of_Smoking | B13: =COUNTBLANK('Raw Data'!E2:E2501) -> 0
A14: Cigarettes_Per_Day | B14: =COUNTBLANK('Raw Data'!F2:F2501) -> 0
A15: Organ | B15: =COUNTBLANK('Raw Data'!G2:G2501) -> 0
A16: Organ_Condition | B16: =COUNTBLANK('Raw Data'!H2:H2501) -> 0
A17: BMI | B17: =COUNTBLANK('Raw Data'!I2:I2501) -> 0
A18: BP_Risk | B18: =COUNTBLANK('Raw Data'!J2:J2501) -> 0
A19: Cholesterol_Level | B19: =COUNTBLANK('Raw Data'!K2:K2501) -> 0
A20: Family_History_Risk | B20: =COUNTBLANK('Raw Data'!L2:L2501) -> 0
A21: Alcohol_Consumption | B21: =COUNTBLANK('Raw Data'!M2:M2501) -> 0
A23: Range check
A24: Field | B24: Min | C24: Max
A25: Age | B25: =MIN('Raw Data'!B2:B2501) -> 18 | C25: =MAX('Raw Data'!B2:B2501) -> 89
A26: BMI | B26: =MIN('Raw Data'!I2:I2501) -> 17 | C26: =MAX('Raw Data'!I2:I2501) -> 42
A27: Cholesterol_Level | B27: =MIN('Raw Data'!K2:K2501) -> 120 | C27: =MAX('Raw Data'!K2:K2501) -> 300
A29: Category consistency
A30: Field | B30: Rows matching known categories | C30: Matches total rows?
A31: Gender | B31: =COUNTIF('Raw Data'!C2:C2501,"Male")+COUNTIF('Raw Data'!C2:C2501,"Female") -> 2500 | C31: =B31=COUNTA('Raw Data'!A2:A2501) -> TRUE
A32: Smoking_Status | B32: =COUNTIF('Raw Data'!D2:D2501,"Current")+COUNTIF('Raw Data'!D2:D2501,"Former")+COUNTIF('Raw Data'!D2:D2501,"Never") -> 2500 | C32: =B32=COUNTA('Raw Data'!A2:A2501) -> TRUE
A33: BP_Risk | B33: =COUNTIF('Raw Data'!J2:J2501,"High")+COUNTIF('Raw Data'!J2:J2501,"Normal")+COUNTIF('Raw Data'!J2:J2501,"Low") -> 2500 | C33: =B33=COUNTA('Raw Data'!A2:A2501) -> TRUE
A34: Alcohol_Consumption | B34: =COUNTIF('Raw Data'!M2:M2501,"High")+COUNTIF('Raw Data'!M2:M2501,"Moderate")+COUNTIF('Raw Data'!M2:M2501,"Low") -> 2500 | C34: =B34=COUNTA('Raw Data'!A2:A2501) -> TRUE
A35: Family_History_Risk | B35: =COUNTIF('Raw Data'!L2:L2501,"Yes")+COUNTIF('Raw Data'!L2:L2501,"No") -> 2500 | C35: =B35=COUNTA('Raw Data'!A2:A2501) -> TRUE
A36: Organ_Condition | B36: =COUNTIF('Raw Data'!H2:H2501,"Healthy")+COUNTIF('Raw Data'!H2:H2501,"Damaged") -> 2500 | C36: =B36=COUNTA('Raw Data'!A2:A2501) -> TRUE

Sheet Risk Score
A1: Patient_ID | B1: Age | C1: Gender | D1: Smoking_Status | E1: BP_Risk | F1: Cholesterol_Level | G1: Family_History_Risk | H1: Alcohol_Consumption | I1: Risk_Score | J1: Risk_Tier
A2: ='Raw Data'!A2 -> 17 | B2: ='Raw Data'!B2 -> 55 | C2: ='Raw Data'!C2 -> Female | D2: ='Raw Data'!D2 -> Never | E2: ='Raw Data'!J2 -> Normal | F2: ='Raw Data'!K2 -> 136.3 | G2: ='Raw Data'!L2 -> No | H2: ='Raw Data'!M2 -> Low | I2: =(IF(D2="Current",3,IF(D2="Former",1,0)))+(IF(E2="High",3,IF(E2="Normal",1,0)))+(IF(F2>=240,2,IF(F2>=200,1,0)))+(IF(G2="Yes",2,0))+(IF(H2="High",2,IF(H2="Moderate",1,0))) -> 1 | J2: =IF(I2>=8,"High",IF(I2>=4,"Medium","Low")) -> Low
A3: ='Raw Data'!A3 -> 18 | B3: ='Raw Data'!B3 -> 20 | C3: ='Raw Data'!C3 -> Female | D3: ='Raw Data'!D3 -> Never | E3: ='Raw Data'!J3 -> Normal | F3: ='Raw Data'!K3 -> 160.8 | G3: ='Raw Data'!L3 -> No | H3: ='Raw Data'!M3 -> Low | I3: =(IF(D3="Current",3,IF(D3="Former",1,0)))+(IF(E3="High",3,IF(E3="Normal",1,0)))+(IF(F3>=240,2,IF(F3>=200,1,0)))+(IF(G3="Yes",2,0))+(IF(H3="High",2,IF(H3="Moderate",1,0))) -> 1 | J3: =IF(I3>=8,"High",IF(I3>=4,"Medium","Low")) -> Low
A4: ='Raw Data'!A4 -> 31 | B4: ='Raw Data'!B4 -> 64 | C4: ='Raw Data'!C4 -> Male | D4: ='Raw Data'!D4 -> Never | E4: ='Raw Data'!J4 -> Normal | F4: ='Raw Data'!K4 -> 127.4 | G4: ='Raw Data'!L4 -> No | H4: ='Raw Data'!M4 -> Low | I4: =(IF(D4="Current",3,IF(D4="Former",1,0)))+(IF(E4="High",3,IF(E4="Normal",1,0)))+(IF(F4>=240,2,IF(F4>=200,1,0)))+(IF(G4="Yes",2,0))+(IF(H4="High",2,IF(H4="Moderate",1,0))) -> 1 | J4: =IF(I4>=8,"High",IF(I4>=4,"Medium","Low")) -> Low
A5: ='Raw Data'!A5 -> 115 | B5: ='Raw Data'!B5 -> 65 | C5: ='Raw Data'!C5 -> Male | D5: ='Raw Data'!D5 -> Never | E5: ='Raw Data'!J5 -> Normal | F5: ='Raw Data'!K5 -> 231.4 | G5: ='Raw Data'!L5 -> No | H5: ='Raw Data'!M5 -> Low | I5: =(IF(D5="Current",3,IF(D5="Former",1,0)))+(IF(E5="High",3,IF(E5="Normal",1,0)))+(IF(F5>=240,2,IF(F5>=200,1,0)))+(IF(G5="Yes",2,0))+(IF(H5="High",2,IF(H5="Moderate",1,0))) -> 2 | J5: =IF(I5>=8,"High",IF(I5>=4,"Medium","Low")) -> Low
A6: ='Raw Data'!A6 -> 135 | B6: ='Raw Data'!B6 -> 24 | C6: ='Raw Data'!C6 -> Female | D6: ='Raw Data'!D6 -> Never | E6: ='Raw Data'!J6 -> Normal | F6: ='Raw Data'!K6 -> 196.6 | G6: ='Raw Data'!L6 -> No | H6: ='Raw Data'!M6 -> Low | I6: =(IF(D6="Current",3,IF(D6="Former",1,0)))+(IF(E6="High",3,IF(E6="Normal",1,0)))+(IF(F6>=240,2,IF(F6>=200,1,0)))+(IF(G6="Yes",2,0))+(IF(H6="High",2,IF(H6="Moderate",1,0))) -> 1 | J6: =IF(I6>=8,"High",IF(I6>=4,"Medium","Low")) -> Low
A7: ='Raw Data'!A7 -> 140 | B7: ='Raw Data'!B7 -> 40 | C7: ='Raw Data'!C7 -> Male | D7: ='Raw Data'!D7 -> Never | E7: ='Raw Data'!J7 -> Normal | F7: ='Raw Data'!K7 -> 200.8 | G7: ='Raw Data'!L7 -> No | H7: ='Raw Data'!M7 -> Low | I7: =(IF(D7="Current",3,IF(D7="Former",1,0)))+(IF(E7="High",3,IF(E7="Normal",1,0)))+(IF(F7>=240,2,IF(F7>=200,1,0)))+(IF(G7="Yes",2,0))+(IF(H7="High",2,IF(H7="Moderate",1,0))) -> 2 | J7: =IF(I7>=8,"High",IF(I7>=4,"Medium","Low")) -> Low
A8: ='Raw Data'!A8 -> 154 | B8: ='Raw Data'!B8 -> 69 | C8: ='Raw Data'!C8 -> Female | D8: ='Raw Data'!D8 -> Never | E8: ='Raw Data'!J8 -> Normal | F8: ='Raw Data'!K8 -> 136.1 | G8: ='Raw Data'!L8 -> No | H8: ='Raw Data'!M8 -> Low | I8: =(IF(D8="Current",3,IF(D8="Former",1,0)))+(IF(E8="High",3,IF(E8="Normal",1,0)))+(IF(F8>=240,2,IF(F8>=200,1,0)))+(IF(G8="Yes",2,0))+(IF(H8="High",2,IF(H8="Moderate",1,0))) -> 1 | J8: =IF(I8>=8,"High",IF(I8>=4,"Medium","Low")) -> Low
A9: ='Raw Data'!A9 -> 159 | B9: ='Raw Data'!B9 -> 54 | C9: ='Raw Data'!C9 -> Male | D9: ='Raw Data'!D9 -> Never | E9: ='Raw Data'!J9 -> Normal | F9: ='Raw Data'!K9 -> 190.4 | G9: ='Raw Data'!L9 -> No | H9: ='Raw Data'!M9 -> Low | I9: =(IF(D9="Current",3,IF(D9="Former",1,0)))+(IF(E9="High",3,IF(E9="Normal",1,0)))+(IF(F9>=240,2,IF(F9>=200,1,0)))+(IF(G9="Yes",2,0))+(IF(H9="High",2,IF(H9="Moderate",1,0))) -> 1 | J9: =IF(I9>=8,"High",IF(I9>=4,"Medium","Low")) -> Low
A10: ='Raw Data'!A10 -> 193 | B10: ='Raw Data'!B10 -> 21 | C10: ='Raw Data'!C10 -> Female | D10: ='Raw Data'!D10 -> Never | E10: ='Raw Data'!J10 -> Normal | F10: ='Raw Data'!K10 -> 194.3 | G10: ='Raw Data'!L10 -> No | H10: ='Raw Data'!M10 -> Low | I10: =(IF(D10="Current",3,IF(D10="Former",1,0)))+(IF(E10="High",3,IF(E10="Normal",1,0)))+(IF(F10>=240,2,IF(F10>=200,1,0)))+(IF(G10="Yes",2,0))+(IF(H10="High",2,IF(H10="Moderate",1,0))) -> 1 | J10: =IF(I10>=8,"High",IF(I10>=4,"Medium","Low")) -> Low
A11: ='Raw Data'!A11 -> 215 | B11: ='Raw Data'!B11 -> 42 | C11: ='Raw Data'!C11 -> Male | D11: ='Raw Data'!D11 -> Never | E11: ='Raw Data'!J11 -> Normal | F11: ='Raw Data'!K11 -> 188.2 | G11: ='Raw Data'!L11 -> No | H11: ='Raw Data'!M11 -> Low | I11: =(IF(D11="Current",3,IF(D11="Former",1,0)))+(IF(E11="High",3,IF(E11="Normal",1,0)))+(IF(F11>=240,2,IF(F11>=200,1,0)))+(IF(G11="Yes",2,0))+(IF(H11="High",2,IF(H11="Moderate",1,0))) -> 1 | J11: =IF(I11>=8,"High",IF(I11>=4,"Medium","Low")) -> Low
A12: ='Raw Data'!A12 -> 233 | B12: ='Raw Data'!B12 -> 26 | C12: ='Raw Data'!C12 -> Female | D12: ='Raw Data'!D12 -> Never | E12: ='Raw Data'!J12 -> Normal | F12: ='Raw Data'!K12 -> 278.4 | G12: ='Raw Data'!L12 -> No | H12: ='Raw Data'!M12 -> Low | I12: =(IF(D12="Current",3,IF(D12="Former",1,0)))+(IF(E12="High",3,IF(E12="Normal",1,0)))+(IF(F12>=240,2,IF(F12>=200,1,0)))+(IF(G12="Yes",2,0))+(IF(H12="High",2,IF(H12="Moderate",1,0))) -> 3 | J12: =IF(I12>=8,"High",IF(I12>=4,"Medium","Low")) -> Low
A13: ='Raw Data'!A13 -> 240 | B13: ='Raw Data'!B13 -> 38 | C13: ='Raw Data'!C13 -> Female | D13: ='Raw Data'!D13 -> Never | E13: ='Raw Data'!J13 -> Normal | F13: ='Raw Data'!K13 -> 175.1 | G13: ='Raw Data'!L13 -> No | H13: ='Raw Data'!M13 -> Low | I13: =(IF(D13="Current",3,IF(D13="Former",1,0)))+(IF(E13="High",3,IF(E13="Normal",1,0)))+(IF(F13>=240,2,IF(F13>=200,1,0)))+(IF(G13="Yes",2,0))+(IF(H13="High",2,IF(H13="Moderate",1,0))) -> 1 | J13: =IF(I13>=8,"High",IF(I13>=4,"Medium","Low")) -> Low
... A2501: ='Raw Data'!A2501 -> 2499 | B2501: ='Raw Data'!B2501 -> 43 | C2501: ='Raw Data'!C2501 -> Female | D2501: ='Raw Data'!D2501 -> Current | E2501: ='Raw Data'!J2501 -> Normal | F2501: ='Raw Data'!K2501 -> 129.3 | G2501: ='Raw Data'!L2501 -> Yes | H2501: ='Raw Data'!M2501 -> Low | I2501: =(IF(D2501="Current",3,IF(D2501="Former",1,0)))+(IF(E2501="High",3,IF(E2501="Normal",1,0)))+(IF(F2501>=240,2,IF(F2501>=200,1,0)))+(IF(G2501="Yes",2,0))+(IF(H2501="High",2,IF(H2501="Moderate",1,0))) -> 6 | J2501: =IF(I2501>=8,"High",IF(I2501>=4,"Medium","Low")) -> Medium

Sheet Priority Screening List
A1: High Risk Patients - Priority Screening
A2: Sorted by Risk Score, highest first. Source: Risk Score sheet.
A4: Patient_ID | B4: Age | C4: Gender | D4: Smoking_Status | E4: BP_Risk | F4: Cholesterol_Level | G4: Family_History_Risk | H4: Alcohol_Consumption | I4: Risk_Score
A5: ='Risk Score'!A1412 -> 577 | B5: ='Risk Score'!B1412 -> 29 | C5: ='Risk Score'!C1412 -> Male | D5: ='Risk Score'!D1412 -> Current | E5: ='Risk Score'!E1412 -> High | F5: ='Risk Score'!F1412 -> 289.3 | G5: ='Risk Score'!G1412 -> Yes | H5: ='Risk Score'!H1412 -> High | I5: ='Risk Score'!I1412 -> 12
A6: ='Risk Score'!A1443 -> 2210 | B6: ='Risk Score'!B1443 -> 67 | C6: ='Risk Score'!C1443 -> Male | D6: ='Risk Score'!D1443 -> Current | E6: ='Risk Score'!E1443 -> High | F6: ='Risk Score'!F1443 -> 270.7 | G6: ='Risk Score'!G1443 -> Yes | H6: ='Risk Score'!H1443 -> High | I6: ='Risk Score'!I1443 -> 12
A7: ='Risk Score'!A1453 -> 69 | B7: ='Risk Score'!B1453 -> 25 | C7: ='Risk Score'!C1453 -> Female | D7: ='Risk Score'!D1453 -> Current | E7: ='Risk Score'!E1453 -> High | F7: ='Risk Score'!F1453 -> 248 | G7: ='Risk Score'!G1453 -> Yes | H7: ='Risk Score'!H1453 -> Moderate | I7: ='Risk Score'!I1453 -> 11
A8: ='Risk Score'!A1464 -> 316 | B8: ='Risk Score'!B1464 -> 23 | C8: ='Risk Score'!C1464 -> Male | D8: ='Risk Score'!D1464 -> Current | E8: ='Risk Score'!E1464 -> High | F8: ='Risk Score'!F1464 -> 274.8 | G8: ='Risk Score'!G1464 -> Yes | H8: ='Risk Score'!H1464 -> Moderate | I8: ='Risk Score'!I1464 -> 11
A9: ='Risk Score'!A1475 -> 593 | B9: ='Risk Score'!B1475 -> 75 | C9: ='Risk Score'!C1475 -> Female | D9: ='Risk Score'!D1475 -> Current | E9: ='Risk Score'!E1475 -> High | F9: ='Risk Score'!F1475 -> 240 | G9: ='Risk Score'!G1475 -> Yes | H9: ='Risk Score'!H1475 -> Moderate | I9: ='Risk Score'!I1475 -> 11
A10: ='Risk Score'!A1436 -> 1877 | B10: ='Risk Score'!B1436 -> 87 | C10: ='Risk Score'!C1436 -> Male | D10: ='Risk Score'!D1436 -> Current | E10: ='Risk Score'!E1436 -> High | F10: ='Risk Score'!F1436 -> 230.3 | G10: ='Risk Score'!G1436 -> Yes | H10: ='Risk Score'!H1436 -> High | I10: ='Risk Score'!I1436 -> 11
A11: ='Risk Score'!A1563 -> 2436 | B11: ='Risk Score'!B1563 -> 79 | C11: ='Risk Score'!C1563 -> Male | D11: ='Risk Score'!D1563 -> Current | E11: ='Risk Score'!E1563 -> High | F11: ='Risk Score'!F1563 -> 245.2 | G11: ='Risk Score'!G1563 -> Yes | H11: ='Risk Score'!H1563 -> Moderate | I11: ='Risk Score'!I1563 -> 11
A12: ='Risk Score'!A1506 -> 1114 | B12: ='Risk Score'!B1506 -> 19 | C12: ='Risk Score'!C1506 -> Female | D12: ='Risk Score'!D1506 -> Current | E12: ='Risk Score'!E1506 -> High | F12: ='Risk Score'!F1506 -> 289.6 | G12: ='Risk Score'!G1506 -> Yes | H12: ='Risk Score'!H1506 -> Moderate | I12: ='Risk Score'!I1506 -> 11
A13: ='Risk Score'!A1435 -> 1870 | B13: ='Risk Score'!B1435 -> 23 | C13: ='Risk Score'!C1435 -> Male | D13: ='Risk Score'!D1435 -> Current | E13: ='Risk Score'!E1435 -> High | F13: ='Risk Score'!F1435 -> 253 | G13: ='Risk Score'!G1435 -> No | H13: ='Risk Score'!H1435 -> High | I13: ='Risk Score'!I1435 -> 10
A14: ='Risk Score'!A1422 -> 1173 | B14: ='Risk Score'!B1422 -> 28 | C14: ='Risk Score'!C1422 -> Female | D14: ='Risk Score'!D1422 -> Former | E14: ='Risk Score'!E1422 -> High | F14: ='Risk Score'!F1422 -> 264.9 | G14: ='Risk Score'!G1422 -> Yes | H14: ='Risk Score'!H1422 -> High | I14: ='Risk Score'!I1422 -> 10
A15: ='Risk Score'!A1441 -> 2096 | B15: ='Risk Score'!B1441 -> 55 | C15: ='Risk Score'!C1441 -> Female | D15: ='Risk Score'!D1441 -> Current | E15: ='Risk Score'!E1441 -> High | F15: ='Risk Score'!F1441 -> 147.7 | G15: ='Risk Score'!G1441 -> Yes | H15: ='Risk Score'!H1441 -> High | I15: ='Risk Score'!I1441 -> 10
A16: ='Risk Score'!A1524 -> 1548 | B16: ='Risk Score'!B1524 -> 72 | C16: ='Risk Score'!C1524 -> Male | D16: ='Risk Score'!D1524 -> Current | E16: ='Risk Score'!E1524 -> High | F16: ='Risk Score'!F1524 -> 221.4 | G16: ='Risk Score'!G1524 -> Yes | H16: ='Risk Score'!H1524 -> Moderate | I16: ='Risk Score'!I1524 -> 10
A17: ='Risk Score'!A1656 -> 21 | B17: ='Risk Score'!B1656 -> 89 | C17: ='Risk Score'!C1656 -> Female | D17: ='Risk Score'!D1656 -> Current | E17: ='Risk Score'!E1656 -> High | F17: ='Risk Score'!F1656 -> 295.3 | G17: ='Risk Score'!G1656 -> Yes | H17: ='Risk Score'!H1656 -> Low | I17: ='Risk Score'!I1656 -> 10
A18: ='Risk Score'!A1511 -> 1227 | B18: ='Risk Score'!B1511 -> 80 | C18: ='Risk Score'!C1511 -> Male | D18: ='Risk Score'!D1511 -> Current | E18: ='Risk Score'!E1511 -> High | F18: ='Risk Score'!F1511 -> 236.4 | G18: ='Risk Score'!G1511 -> Yes | H18: ='Risk Score'!H1511 -> Moderate | I18: ='Risk Score'!I1511 -> 10
A19: ='Risk Score'!A1448 -> 2435 | B19: ='Risk Score'!B1448 -> 63 | C19: ='Risk Score'!C1448 -> Female | D19: ='Risk Score'!D1448 -> Current | E19: ='Risk Score'!E1448 -> High | F19: ='Risk Score'!F1448 -> 148.3 | G19: ='Risk Score'!G1448 -> Yes | H19: ='Risk Score'!H1448 -> High | I19: ='Risk Score'!I1448 -> 10
A20: ='Risk Score'!A1447 -> 2431 | B20: ='Risk Score'!B1447 -> 75 | C20: ='Risk Score'!C1447 -> Male | D20: ='Risk Score'!D1447 -> Current | E20: ='Risk Score'!E1447 -> High | F20: ='Risk Score'!F1447 -> 246.2 | G20: ='Risk Score'!G1447 -> No | H20: ='Risk Score'!H1447 -> High | I20: ='Risk Score'!I1447 -> 10
A21: ='Risk Score'!A1437 -> 1895 | B21: ='Risk Score'!B1437 -> 61 | C21: ='Risk Score'!C1437 -> Female | D21: ='Risk Score'!D1437 -> Current | E21: ='Risk Score'!E1437 -> High | F21: ='Risk Score'!F1437 -> 272.4 | G21: ='Risk Score'!G1437 -> No | H21: ='Risk Score'!H1437 -> High | I21: ='Risk Score'!I1437 -> 10
A22: ='Risk Score'!A1420 -> 994 | B22: ='Risk Score'!B1420 -> 56 | C22: ='Risk Score'!C1420 -> Male | D22: ='Risk Score'!D1420 -> Current | E22: ='Risk Score'!E1420 -> High | F22: ='Risk Score'!F1420 -> 254.7 | G22: ='Risk Score'!G1420 -> No | H22: ='Risk Score'!H1420 -> High | I22: ='Risk Score'!I1420 -> 10
A23: ='Risk Score'!A1406 -> 341 | B23: ='Risk Score'!B1406 -> 35 | C23: ='Risk Score'!C1406 -> Female | D23: ='Risk Score'!D1406 -> Current | E23: ='Risk Score'!E1406 -> High | F23: ='Risk Score'!F1406 -> 268.8 | G23: ='Risk Score'!G1406 -> No | H23: ='Risk Score'!H1406 -> High | I23: ='Risk Score'!I1406 -> 10
A24: ='Risk Score'!A1409 -> 532 | B24: ='Risk Score'!B1409 -> 66 | C24: ='Risk Score'!C1409 -> Female | D24: ='Risk Score'!D1409 -> Current | E24: ='Risk Score'!E1409 -> High | F24: ='Risk Score'!F1409 -> 261.3 | G24: ='Risk Score'!G1409 -> No | H24: ='Risk Score'!H1409 -> High | I24: ='Risk Score'!I1409 -> 10
A25: ='Risk Score'!A1424 -> 1259 | B25: ='Risk Score'!B1424 -> 71 | C25: ='Risk Score'!C1424 -> Male | D25: ='Risk Score'!D1424 -> Current | E25: ='Risk Score'!E1424 -> High | F25: ='Risk Score'!F1424 -> 290.6 | G25: ='Risk Score'!G1424 -> No | H25: ='Risk Score'!H1424 -> High | I25: ='Risk Score'!I1424 -> 10
A26: ='Risk Score'!A1667 -> 396 | B26: ='Risk Score'!B1667 -> 65 | C26: ='Risk Score'!C1667 -> Female | D26: ='Risk Score'!D1667 -> Current | E26: ='Risk Score'!E1667 -> High | F26: ='Risk Score'!F1667 -> 295.4 | G26: ='Risk Score'!G1667 -> Yes | H26: ='Risk Score'!H1667 -> Low | I26: ='Risk Score'!I1667 -> 10
A27: ='Risk Score'!A1696 -> 1121 | B27: ='Risk Score'!B1696 -> 86 | C27: ='Risk Score'!C1696 -> Male | D27: ='Risk Score'!D1696 -> Current | E27: ='Risk Score'!E1696 -> High | F27: ='Risk Score'!F1696 -> 299.6 | G27: ='Risk Score'!G1696 -> Yes | H27: ='Risk Score'!H1696 -> Low | I27: ='Risk Score'!I1696 -> 10
A28: ='Risk Score'!A2128 -> 1868 | B28: ='Risk Score'!B2128 -> 32 | C28: ='Risk Score'!C2128 -> Male | D28: ='Risk Score'!D2128 -> Current | E28: ='Risk Score'!E2128 -> Normal | F28: ='Risk Score'!F2128 -> 293 | G28: ='Risk Score'!G2128 -> Yes | H28: ='Risk Score'!H2128 -> High | I28: ='Risk Score'!I2128 -> 10
A29: ='Risk Score'!A1723 -> 1931 | B29: ='Risk Score'!B1723 -> 88 | C29: ='Risk Score'!C1723 -> Male | D29: ='Risk Score'!D1723 -> Current | E29: ='Risk Score'!E1723 -> High | F29: ='Risk Score'!F1723 -> 288.3 | G29: ='Risk Score'!G1723 -> Yes | H29: ='Risk Score'!H1723 -> Low | I29: ='Risk Score'!I1723 -> 10
A30: ='Risk Score'!A1724 -> 1943 | B30: ='Risk Score'!B1724 -> 22 | C30: ='Risk Score'!C1724 -> Female | D30: ='Risk Score'!D1724 -> Current | E30: ='Risk Score'!E1724 -> High | F30: ='Risk Score'!F1724 -> 270.2 | G30: ='Risk Score'!G1724 -> Yes | H30: ='Risk Score'!H1724 -> Low | I30: ='Risk Score'!I1724 -> 10
A31: ='Risk Score'!A2121 -> 1799 | B31: ='Risk Score'!B2121 -> 83 | C31: ='Risk Score'!C2121 -> Female | D31: ='Risk Score'!D2121 -> Current | E31: ='Risk Score'!E2121 -> Normal | F31: ='Risk Score'!F2121 -> 288.9 | G31: ='Risk Score'!G2121 -> Yes | H31: ='Risk Score'!H2121 -> High | I31: ='Risk Score'!I2121 -> 10
A32: ='Risk Score'!A2090 -> 411 | B32: ='Risk Score'!B2090 -> 68 | C32: ='Risk Score'!C2090 -> Female | D32: ='Risk Score'!D2090 -> Current | E32: ='Risk Score'!E2090 -> Normal | F32: ='Risk Score'!F2090 -> 293.8 | G32: ='Risk Score'!G2090 -> Yes | H32: ='Risk Score'!H2090 -> High | I32: ='Risk Score'!I2090 -> 10
A33: ='Risk Score'!A2081 -> 47 | B33: ='Risk Score'!B2081 -> 79 | C33: ='Risk Score'!C2081 -> Male | D33: ='Risk Score'!D2081 -> Current | E33: ='Risk Score'!E2081 -> Normal | F33: ='Risk Score'!F2081 -> 293.4 | G33: ='Risk Score'!G2081 -> Yes | H33: ='Risk Score'!H2081 -> High | I33: ='Risk Score'!I2081 -> 10
A34: ='Risk Score'!A2083 -> 92 | B34: ='Risk Score'!B2083 -> 29 | C34: ='Risk Score'!C2083 -> Female | D34: ='Risk Score'!D2083 -> Current | E34: ='Risk Score'!E2083 -> Normal | F34: ='Risk Score'!F2083 -> 275 | G34: ='Risk Score'!G2083 -> Yes | H34: ='Risk Score'!H2083 -> High | I34: ='Risk Score'!I2083 -> 10
A35: ='Risk Score'!A1674 -> 664 | B35: ='Risk Score'!B1674 -> 89 | C35: ='Risk Score'!C1674 -> Male | D35: ='Risk Score'!D1674 -> Current | E35: ='Risk Score'!E1674 -> High | F35: ='Risk Score'!F1674 -> 295.1 | G35: ='Risk Score'!G1674 -> Yes | H35: ='Risk Score'!H1674 -> Low | I35: ='Risk Score'!I1674 -> 10
A36: ='Risk Score'!A1702 -> 1235 | B36: ='Risk Score'!B1702 -> 74 | C36: ='Risk Score'!C1702 -> Female | D36: ='Risk Score'!D1702 -> Current | E36: ='Risk Score'!E1702 -> High | F36: ='Risk Score'!F1702 -> 259.3 | G36: ='Risk Score'!G1702 -> Yes | H36: ='Risk Score'!H1702 -> Low | I36: ='Risk Score'!I1702 -> 10
A37: ='Risk Score'!A1705 -> 1299 | B37: ='Risk Score'!B1705 -> 52 | C37: ='Risk Score'!C1705 -> Female | D37: ='Risk Score'!D1705 -> Current | E37: ='Risk Score'!E1705 -> High | F37: ='Risk Score'!F1705 -> 288.3 | G37: ='Risk Score'!G1705 -> Yes | H37: ='Risk Score'!H1705 -> Low | I37: ='Risk Score'!I1705 -> 10
A38: ='Risk Score'!A1721 -> 1874 | B38: ='Risk Score'!B1721 -> 70 | C38: ='Risk Score'!C1721 -> Male | D38: ='Risk Score'!D1721 -> Current | E38: ='Risk Score'!E1721 -> High | F38: ='Risk Score'!F1721 -> 265.2 | G38: ='Risk Score'!G1721 -> Yes | H38: ='Risk Score'!H1721 -> Low | I38: ='Risk Score'!I1721 -> 10
A39: ='Risk Score'!A1686 -> 885 | B39: ='Risk Score'!B1686 -> 84 | C39: ='Risk Score'!C1686 -> Male | D39: ='Risk Score'!D1686 -> Current | E39: ='Risk Score'!E1686 -> High | F39: ='Risk Score'!F1686 -> 246.5 | G39: ='Risk Score'!G1686 -> Yes | H39: ='Risk Score'!H1686 -> Low | I39: ='Risk Score'!I1686 -> 10
A40: ='Risk Score'!A1681 -> 767 | B40: ='Risk Score'!B1681 -> 62 | C40: ='Risk Score'!C1681 -> Male | D40: ='Risk Score'!D1681 -> Current | E40: ='Risk Score'!E1681 -> High | F40: ='Risk Score'!F1681 -> 286 | G40: ='Risk Score'!G1681 -> Yes | H40: ='Risk Score'!H1681 -> Low | I40: ='Risk Score'!I1681 -> 10
A41: ='Risk Score'!A1449 -> 2455 | B41: ='Risk Score'!B1449 -> 61 | C41: ='Risk Score'!C1449 -> Male | D41: ='Risk Score'!D1449 -> Current | E41: ='Risk Score'!E1449 -> High | F41: ='Risk Score'!F1449 -> 206.3 | G41: ='Risk Score'!G1449 -> No | H41: ='Risk Score'!H1449 -> High | I41: ='Risk Score'!I1449 -> 9
...
